ERROR 2024-10-26 15:01:50,202 signals 11660 9340 Signal Error - Type: pre_save, Model: UserProfile, ID: 12532b9d-bcfa-412f-b891-a7b3aff7b20e, Error: UserProfile matching query does not exist.
ERROR 2024-10-26 15:01:50,203 signals 11660 9340 Signal Error - Type: post_save, Model: User, ID: 72758f9a-3742-4106-be73-f0d10c18f35b, Error: Error in handle_profile_image: UserProfile matching query does not exist.
ERROR 2024-10-26 15:01:50,203 models 11660 9340 Error saving user test@example.com: Error in user_post_save: Error in handle_profile_image: UserProfile matching query does not exist.
ERROR 2024-10-26 15:01:50,204 models 11660 9340 Error creating user: Error in user_post_save: Error in handle_profile_image: UserProfile matching query does not exist.
ERROR 2024-10-26 15:01:50,977 signals 11660 9340 Signal Error - Type: pre_save, Model: UserProfile, ID: a615e124-8af6-47e1-88f1-0ec777153844, Error: UserProfile matching query does not exist.
ERROR 2024-10-26 15:01:50,978 signals 11660 9340 Signal Error - Type: post_save, Model: User, ID: 63e9e37f-e88a-48ba-b95a-475d03253ec4, Error: Error in handle_profile_image: UserProfile matching query does not exist.
ERROR 2024-10-26 15:01:50,979 models 11660 9340 Error saving user test@example.com: Error in user_post_save: Error in handle_profile_image: UserProfile matching query does not exist.
ERROR 2024-10-26 15:01:50,979 models 11660 9340 Error creating user: Error in user_post_save: Error in handle_profile_image: UserProfile matching query does not exist.
ERROR 2024-10-26 15:01:51,837 signals 11660 9340 Signal Error - Type: pre_save, Model: UserProfile, ID: 29d12692-95fa-4aa8-aabe-80e2b195fd9d, Error: UserProfile matching query does not exist.
ERROR 2024-10-26 15:01:51,838 signals 11660 9340 Signal Error - Type: post_save, Model: User, ID: 7a0e4b3a-ca85-4805-a3da-0a05a5d6399c, Error: Error in handle_profile_image: UserProfile matching query does not exist.
ERROR 2024-10-26 15:01:51,838 models 11660 9340 Error saving user test@example.com: Error in user_post_save: Error in handle_profile_image: UserProfile matching query does not exist.
ERROR 2024-10-26 15:01:51,839 models 11660 9340 Error creating user: Error in user_post_save: Error in handle_profile_image: UserProfile matching query does not exist.
ERROR 2024-10-26 15:01:52,611 signals 11660 9340 Signal Error - Type: pre_save, Model: UserProfile, ID: fc811f39-e0f8-4a62-a0b7-fc8f06eb7196, Error: UserProfile matching query does not exist.
ERROR 2024-10-26 15:01:52,612 signals 11660 9340 Signal Error - Type: post_save, Model: User, ID: 8364f091-0e38-4c2f-b415-13ab559f0ca6, Error: Error in handle_profile_image: UserProfile matching query does not exist.
ERROR 2024-10-26 15:01:52,612 models 11660 9340 Error saving user test@example.com: Error in user_post_save: Error in handle_profile_image: UserProfile matching query does not exist.
ERROR 2024-10-26 15:01:52,613 models 11660 9340 Error creating user: Error in user_post_save: Error in handle_profile_image: UserProfile matching query does not exist.
ERROR 2024-10-26 15:01:53,376 signals 11660 9340 Signal Error - Type: pre_save, Model: UserProfile, ID: 901a7b47-4fbd-49bd-a537-5469d0815607, Error: UserProfile matching query does not exist.
ERROR 2024-10-26 15:01:53,377 signals 11660 9340 Signal Error - Type: post_save, Model: User, ID: c3143abe-bdb4-484b-8c49-cf489b7e97d2, Error: Error in handle_profile_image: UserProfile matching query does not exist.
ERROR 2024-10-26 15:01:53,378 models 11660 9340 Error saving user test@example.com: Error in user_post_save: Error in handle_profile_image: UserProfile matching query does not exist.
ERROR 2024-10-26 15:01:53,378 models 11660 9340 Error creating user: Error in user_post_save: Error in handle_profile_image: UserProfile matching query does not exist.
ERROR 2024-10-26 15:01:54,299 signals 11660 9340 Signal Error - Type: pre_save, Model: UserProfile, ID: c1893773-7380-486f-8761-a70a3ed6b035, Error: UserProfile matching query does not exist.
ERROR 2024-10-26 15:01:54,300 signals 11660 9340 Signal Error - Type: post_save, Model: User, ID: 42a7c78a-a9ea-43f6-8f2c-004cf980a9a2, Error: Error in handle_profile_image: UserProfile matching query does not exist.
ERROR 2024-10-26 15:01:54,301 models 11660 9340 Error saving user test@example.com: Error in user_post_save: Error in handle_profile_image: UserProfile matching query does not exist.
ERROR 2024-10-26 15:01:54,301 models 11660 9340 Error creating user: Error in user_post_save: Error in handle_profile_image: UserProfile matching query does not exist.
ERROR 2024-10-26 15:01:54,301 test_initial 11660 9340 Test failed: Error in user_post_save: Error in handle_profile_image: UserProfile matching query does not exist.
ERROR 2024-10-27 11:35:27,124 signals 12560 5588 Signal Error - Type: pre_save, Model: UserProfile, ID: 15b373bb-bebc-4d4e-a23f-d04b8fe76ad3, Error: UserProfile matching query does not exist.
ERROR 2024-10-27 11:35:27,125 signals 12560 5588 Signal Error - Type: post_save, Model: User, ID: 8c8ebe43-d903-4973-8879-1884f941dbdf, Error: Error in handle_profile_image: UserProfile matching query does not exist.
ERROR 2024-10-27 11:35:27,126 models 12560 5588 Error saving user test@example.com: Error in user_post_save: Error in handle_profile_image: UserProfile matching query does not exist.
ERROR 2024-10-27 11:35:27,126 models 12560 5588 Error creating user: Error in user_post_save: Error in handle_profile_image: UserProfile matching query does not exist.
ERROR 2024-10-27 11:35:28,007 signals 12560 5588 Signal Error - Type: pre_save, Model: UserProfile, ID: 84a2c255-17a2-4ac7-9110-f794531cb898, Error: UserProfile matching query does not exist.
ERROR 2024-10-27 11:35:28,008 signals 12560 5588 Signal Error - Type: post_save, Model: User, ID: 473d88f0-d323-4bc7-976b-6545fff22e39, Error: Error in handle_profile_image: UserProfile matching query does not exist.
ERROR 2024-10-27 11:35:28,009 models 12560 5588 Error saving user test@example.com: Error in user_post_save: Error in handle_profile_image: UserProfile matching query does not exist.
ERROR 2024-10-27 11:35:28,009 models 12560 5588 Error creating user: Error in user_post_save: Error in handle_profile_image: UserProfile matching query does not exist.
ERROR 2024-10-27 11:35:28,973 signals 12560 5588 Signal Error - Type: pre_save, Model: UserProfile, ID: 282c1735-f039-4def-96cd-fe09550dacdc, Error: UserProfile matching query does not exist.
ERROR 2024-10-27 11:35:28,974 signals 12560 5588 Signal Error - Type: post_save, Model: User, ID: 50443b3d-9b57-4f91-889e-94c916144297, Error: Error in handle_profile_image: UserProfile matching query does not exist.
ERROR 2024-10-27 11:35:28,974 models 12560 5588 Error saving user test@example.com: Error in user_post_save: Error in handle_profile_image: UserProfile matching query does not exist.
ERROR 2024-10-27 11:35:28,975 models 12560 5588 Error creating user: Error in user_post_save: Error in handle_profile_image: UserProfile matching query does not exist.
ERROR 2024-10-27 11:35:29,753 signals 12560 5588 Signal Error - Type: pre_save, Model: UserProfile, ID: 2bf6f902-01e1-4c84-8513-bbe1b184ac2b, Error: UserProfile matching query does not exist.
ERROR 2024-10-27 11:35:29,754 signals 12560 5588 Signal Error - Type: post_save, Model: User, ID: b4962b0c-a1c9-4eec-ac94-e5a06c412930, Error: Error in handle_profile_image: UserProfile matching query does not exist.
ERROR 2024-10-27 11:35:29,754 models 12560 5588 Error saving user test@example.com: Error in user_post_save: Error in handle_profile_image: UserProfile matching query does not exist.
ERROR 2024-10-27 11:35:29,755 models 12560 5588 Error creating user: Error in user_post_save: Error in handle_profile_image: UserProfile matching query does not exist.
ERROR 2024-10-27 11:35:30,535 signals 12560 5588 Signal Error - Type: pre_save, Model: UserProfile, ID: 1413a1ad-e0a0-4ee2-8e4f-55abe23adb94, Error: UserProfile matching query does not exist.
ERROR 2024-10-27 11:35:30,536 signals 12560 5588 Signal Error - Type: post_save, Model: User, ID: 092a9314-0bc9-44c6-891d-77dbff2f5c7b, Error: Error in handle_profile_image: UserProfile matching query does not exist.
ERROR 2024-10-27 11:35:30,536 models 12560 5588 Error saving user test@example.com: Error in user_post_save: Error in handle_profile_image: UserProfile matching query does not exist.
ERROR 2024-10-27 11:35:30,537 models 12560 5588 Error creating user: Error in user_post_save: Error in handle_profile_image: UserProfile matching query does not exist.
ERROR 2024-10-27 11:35:31,381 signals 12560 5588 Signal Error - Type: pre_save, Model: UserProfile, ID: 1fcff2e1-e58b-46da-8ec6-b24a143c7cdf, Error: UserProfile matching query does not exist.
ERROR 2024-10-27 11:35:31,382 signals 12560 5588 Signal Error - Type: post_save, Model: User, ID: f2fe8640-9dc6-4282-bb71-16ce4526307e, Error: Error in handle_profile_image: UserProfile matching query does not exist.
ERROR 2024-10-27 11:35:31,383 models 12560 5588 Error saving user test@example.com: Error in user_post_save: Error in handle_profile_image: UserProfile matching query does not exist.
ERROR 2024-10-27 11:35:31,383 models 12560 5588 Error creating user: Error in user_post_save: Error in handle_profile_image: UserProfile matching query does not exist.
ERROR 2024-10-27 11:35:31,383 test_initial 12560 5588 Test failed: Error in user_post_save: Error in handle_profile_image: UserProfile matching query does not exist.
ERROR 2024-10-27 14:24:43,471 log 3612 11736 Internal Server Error: /api/users/profile/me/
Traceback (most recent call last):
  File "C:\Users\kemosabe\Documents\traoning_management\backend\venv\Lib\site-packages\django\core\handlers\exception.py", line 55, in inner
    response = get_response(request)
               ^^^^^^^^^^^^^^^^^^^^^
  File "C:\Users\kemosabe\Documents\traoning_management\backend\venv\Lib\site-packages\django\core\handlers\base.py", line 197, in _get_response
    response = wrapped_callback(request, *callback_args, **callback_kwargs)
               ^^^^^^^^^^^^^^^^^^^^^^^^^^^^^^^^^^^^^^^^^^^^^^^^^^^^^^^^^^^^
  File "C:\Program Files\WindowsApps\PythonSoftwareFoundation.Python.3.12_3.12.2032.0_x64__qbz5n2kfra8p0\Lib\contextlib.py", line 81, in inner
    return func(*args, **kwds)
           ^^^^^^^^^^^^^^^^^^^
  File "C:\Users\kemosabe\Documents\traoning_management\backend\venv\Lib\site-packages\django\views\decorators\csrf.py", line 56, in wrapper_view
    return view_func(*args, **kwargs)
           ^^^^^^^^^^^^^^^^^^^^^^^^^^
  File "C:\Users\kemosabe\Documents\traoning_management\backend\venv\Lib\site-packages\django\views\generic\base.py", line 104, in view
    return self.dispatch(request, *args, **kwargs)
           ^^^^^^^^^^^^^^^^^^^^^^^^^^^^^^^^^^^^^^^
  File "C:\Users\kemosabe\Documents\traoning_management\backend\venv\Lib\site-packages\rest_framework\views.py", line 509, in dispatch
    response = self.handle_exception(exc)
               ^^^^^^^^^^^^^^^^^^^^^^^^^^
  File "C:\Users\kemosabe\Documents\traoning_management\backend\venv\Lib\site-packages\rest_framework\views.py", line 469, in handle_exception
    self.raise_uncaught_exception(exc)
  File "C:\Users\kemosabe\Documents\traoning_management\backend\venv\Lib\site-packages\rest_framework\views.py", line 480, in raise_uncaught_exception
    raise exc
  File "C:\Users\kemosabe\Documents\traoning_management\backend\venv\Lib\site-packages\rest_framework\views.py", line 506, in dispatch
    response = handler(request, *args, **kwargs)
               ^^^^^^^^^^^^^^^^^^^^^^^^^^^^^^^^^
  File "C:\Users\kemosabe\Documents\traoning_management\backend\venv\Lib\site-packages\rest_framework\generics.py", line 252, in get
    return self.retrieve(request, *args, **kwargs)
           ^^^^^^^^^^^^^^^^^^^^^^^^^^^^^^^^^^^^^^^
  File "C:\Users\kemosabe\Documents\traoning_management\backend\venv\Lib\site-packages\rest_framework\mixins.py", line 56, in retrieve
    return Response(serializer.data)
                    ^^^^^^^^^^^^^^^
  File "C:\Users\kemosabe\Documents\traoning_management\backend\venv\Lib\site-packages\rest_framework\serializers.py", line 555, in data
    ret = super().data
          ^^^^^^^^^^^^
  File "C:\Users\kemosabe\Documents\traoning_management\backend\venv\Lib\site-packages\rest_framework\serializers.py", line 253, in data
    self._data = self.to_representation(self.instance)
                 ^^^^^^^^^^^^^^^^^^^^^^^^^^^^^^^^^^^^^
  File "C:\Users\kemosabe\Documents\traoning_management\backend\venv\Lib\site-packages\rest_framework\serializers.py", line 522, in to_representation
    ret[field.field_name] = field.to_representation(attribute)
                            ^^^^^^^^^^^^^^^^^^^^^^^^^^^^^^^^^^
  File "C:\Users\kemosabe\Documents\traoning_management\backend\venv\Lib\site-packages\rest_framework\fields.py", line 1838, in to_representation
    return method(value)
           ^^^^^^^^^^^^^
  File "C:\Users\kemosabe\Documents\traoning_management\backend\apps\users\serializers.py", line 116, in get_total_points
    total=models.Sum('achievement__points')
          ^^^^^^
NameError: name 'models' is not defined
ERROR 2024-10-30 10:06:53,380 signals 14076 3132 Signal Error - Type: pre_save, Model: UserSkill, ID: f74f5faf-5004-4050-8c5a-530f6232e26c, Error: UserSkill matching query does not exist.
ERROR 2024-10-30 10:06:53,416 log 14076 3132 Internal Server Error: /api/users/users/21ee6c60-78e7-467c-966c-65eb4d71fcd7/skills/
Traceback (most recent call last):
  File "C:\Users\kemosabe\Documents\traoning_management\backend\apps\users\signals.py", line 226, in skill_verification_validation
    old_instance = UserSkill.objects.get(id=instance.id)
                   ^^^^^^^^^^^^^^^^^^^^^^^^^^^^^^^^^^^^^
  File "C:\Users\kemosabe\Documents\traoning_management\backend\venv\Lib\site-packages\django\db\models\manager.py", line 87, in manager_method
    return getattr(self.get_queryset(), name)(*args, **kwargs)
           ^^^^^^^^^^^^^^^^^^^^^^^^^^^^^^^^^^^^^^^^^^^^^^^^^^^
  File "C:\Users\kemosabe\Documents\traoning_management\backend\venv\Lib\site-packages\django\db\models\query.py", line 637, in get
    raise self.model.DoesNotExist(
apps.users.models.UserSkill.DoesNotExist: UserSkill matching query does not exist.

During handling of the above exception, another exception occurred:

Traceback (most recent call last):
  File "C:\Users\kemosabe\Documents\traoning_management\backend\venv\Lib\site-packages\django\core\handlers\exception.py", line 55, in inner
    response = get_response(request)
               ^^^^^^^^^^^^^^^^^^^^^
  File "C:\Users\kemosabe\Documents\traoning_management\backend\venv\Lib\site-packages\django\core\handlers\base.py", line 197, in _get_response
    response = wrapped_callback(request, *callback_args, **callback_kwargs)
               ^^^^^^^^^^^^^^^^^^^^^^^^^^^^^^^^^^^^^^^^^^^^^^^^^^^^^^^^^^^^
  File "C:\Program Files\WindowsApps\PythonSoftwareFoundation.Python.3.12_3.12.2032.0_x64__qbz5n2kfra8p0\Lib\contextlib.py", line 81, in inner
    return func(*args, **kwds)
           ^^^^^^^^^^^^^^^^^^^
  File "C:\Users\kemosabe\Documents\traoning_management\backend\venv\Lib\site-packages\django\views\decorators\csrf.py", line 56, in wrapper_view
    return view_func(*args, **kwargs)
           ^^^^^^^^^^^^^^^^^^^^^^^^^^
  File "C:\Users\kemosabe\Documents\traoning_management\backend\venv\Lib\site-packages\rest_framework\viewsets.py", line 125, in view
    return self.dispatch(request, *args, **kwargs)
           ^^^^^^^^^^^^^^^^^^^^^^^^^^^^^^^^^^^^^^^
  File "C:\Users\kemosabe\Documents\traoning_management\backend\venv\Lib\site-packages\rest_framework\views.py", line 509, in dispatch
    response = self.handle_exception(exc)
               ^^^^^^^^^^^^^^^^^^^^^^^^^^
  File "C:\Users\kemosabe\Documents\traoning_management\backend\venv\Lib\site-packages\rest_framework\views.py", line 469, in handle_exception
    self.raise_uncaught_exception(exc)
  File "C:\Users\kemosabe\Documents\traoning_management\backend\venv\Lib\site-packages\rest_framework\views.py", line 480, in raise_uncaught_exception
    raise exc
  File "C:\Users\kemosabe\Documents\traoning_management\backend\venv\Lib\site-packages\rest_framework\views.py", line 506, in dispatch
    response = handler(request, *args, **kwargs)
               ^^^^^^^^^^^^^^^^^^^^^^^^^^^^^^^^^
  File "C:\Users\kemosabe\Documents\traoning_management\backend\venv\Lib\site-packages\rest_framework\mixins.py", line 19, in create
    self.perform_create(serializer)
  File "C:\Users\kemosabe\Documents\traoning_management\backend\venv\Lib\site-packages\rest_framework\mixins.py", line 24, in perform_create
    serializer.save()
  File "C:\Users\kemosabe\Documents\traoning_management\backend\venv\Lib\site-packages\rest_framework\serializers.py", line 212, in save
    self.instance = self.create(validated_data)
                    ^^^^^^^^^^^^^^^^^^^^^^^^^^^
  File "C:\Users\kemosabe\Documents\traoning_management\backend\venv\Lib\site-packages\rest_framework\serializers.py", line 962, in create
    instance = ModelClass._default_manager.create(**validated_data)
               ^^^^^^^^^^^^^^^^^^^^^^^^^^^^^^^^^^^^^^^^^^^^^^^^^^^^
  File "C:\Users\kemosabe\Documents\traoning_management\backend\venv\Lib\site-packages\django\db\models\manager.py", line 87, in manager_method
    return getattr(self.get_queryset(), name)(*args, **kwargs)
           ^^^^^^^^^^^^^^^^^^^^^^^^^^^^^^^^^^^^^^^^^^^^^^^^^^^
  File "C:\Users\kemosabe\Documents\traoning_management\backend\venv\Lib\site-packages\django\db\models\query.py", line 658, in create
    obj.save(force_insert=True, using=self.db)
  File "C:\Users\kemosabe\Documents\traoning_management\backend\venv\Lib\site-packages\django\db\models\base.py", line 814, in save
    self.save_base(
  File "C:\Users\kemosabe\Documents\traoning_management\backend\venv\Lib\site-packages\django\db\models\base.py", line 861, in save_base
    pre_save.send(
  File "C:\Users\kemosabe\Documents\traoning_management\backend\venv\Lib\site-packages\django\dispatch\dispatcher.py", line 177, in send
    (receiver, receiver(signal=self, sender=sender, **named))
               ^^^^^^^^^^^^^^^^^^^^^^^^^^^^^^^^^^^^^^^^^^^^^
  File "C:\Users\kemosabe\Documents\traoning_management\backend\apps\users\signals.py", line 272, in skill_verification_validation
    raise SignalError(f"Error in skill_verification_validation: {str(e)}")
apps.users.signals.SignalError: Error in skill_verification_validation: UserSkill matching query does not exist.
ERROR 2024-10-30 10:07:01,595 signals 14076 3132 Signal Error - Type: pre_save, Model: UserSkill, ID: 09a115f0-9bdf-47a8-b7aa-d8e8038f037f, Error: UserSkill matching query does not exist.
ERROR 2024-10-30 10:07:03,083 signals 14076 3132 Signal Error - Type: pre_save, Model: UserSkill, ID: 90c865d0-2df2-4908-b34d-da7c56d5423f, Error: UserSkill matching query does not exist.
ERROR 2024-10-30 10:48:28,768 log 2180 14232 Internal Server Error: /api/users/users/184bc9a5-99f9-447a-a0d7-ffcf8c263ed0/skills/
Traceback (most recent call last):
  File "C:\Users\kemosabe\Documents\traoning_management\backend\venv\Lib\site-packages\django\db\backends\utils.py", line 89, in _execute
    return self.cursor.execute(sql, params)
           ^^^^^^^^^^^^^^^^^^^^^^^^^^^^^^^^
psycopg2.errors.NotNullViolation: null value in column "user_profile_id" of relation "users_userskill" violates not-null constraint
DETAIL:  Failing row contains (1ba2cedd-2689-4a57-a4df-4c67d1fedc83, INTERMEDIATE, f, null, [], 33fac3e3-0195-476c-9b8e-fd79d79830e7, null, null).


The above exception was the direct cause of the following exception:

Traceback (most recent call last):
  File "C:\Users\kemosabe\Documents\traoning_management\backend\venv\Lib\site-packages\django\core\handlers\exception.py", line 55, in inner
    response = get_response(request)
               ^^^^^^^^^^^^^^^^^^^^^
  File "C:\Users\kemosabe\Documents\traoning_management\backend\venv\Lib\site-packages\django\core\handlers\base.py", line 197, in _get_response
    response = wrapped_callback(request, *callback_args, **callback_kwargs)
               ^^^^^^^^^^^^^^^^^^^^^^^^^^^^^^^^^^^^^^^^^^^^^^^^^^^^^^^^^^^^
  File "C:\Program Files\WindowsApps\PythonSoftwareFoundation.Python.3.12_3.12.2032.0_x64__qbz5n2kfra8p0\Lib\contextlib.py", line 81, in inner
    return func(*args, **kwds)
           ^^^^^^^^^^^^^^^^^^^
  File "C:\Users\kemosabe\Documents\traoning_management\backend\venv\Lib\site-packages\django\views\decorators\csrf.py", line 56, in wrapper_view
    return view_func(*args, **kwargs)
           ^^^^^^^^^^^^^^^^^^^^^^^^^^
  File "C:\Users\kemosabe\Documents\traoning_management\backend\venv\Lib\site-packages\rest_framework\viewsets.py", line 125, in view
    return self.dispatch(request, *args, **kwargs)
           ^^^^^^^^^^^^^^^^^^^^^^^^^^^^^^^^^^^^^^^
  File "C:\Users\kemosabe\Documents\traoning_management\backend\venv\Lib\site-packages\rest_framework\views.py", line 509, in dispatch
    response = self.handle_exception(exc)
               ^^^^^^^^^^^^^^^^^^^^^^^^^^
  File "C:\Users\kemosabe\Documents\traoning_management\backend\venv\Lib\site-packages\rest_framework\views.py", line 469, in handle_exception
    self.raise_uncaught_exception(exc)
  File "C:\Users\kemosabe\Documents\traoning_management\backend\venv\Lib\site-packages\rest_framework\views.py", line 480, in raise_uncaught_exception
    raise exc
  File "C:\Users\kemosabe\Documents\traoning_management\backend\venv\Lib\site-packages\rest_framework\views.py", line 506, in dispatch
    response = handler(request, *args, **kwargs)
               ^^^^^^^^^^^^^^^^^^^^^^^^^^^^^^^^^
  File "C:\Users\kemosabe\Documents\traoning_management\backend\venv\Lib\site-packages\rest_framework\mixins.py", line 19, in create
    self.perform_create(serializer)
  File "C:\Users\kemosabe\Documents\traoning_management\backend\venv\Lib\site-packages\rest_framework\mixins.py", line 24, in perform_create
    serializer.save()
  File "C:\Users\kemosabe\Documents\traoning_management\backend\venv\Lib\site-packages\rest_framework\serializers.py", line 212, in save
    self.instance = self.create(validated_data)
                    ^^^^^^^^^^^^^^^^^^^^^^^^^^^
  File "C:\Users\kemosabe\Documents\traoning_management\backend\venv\Lib\site-packages\rest_framework\serializers.py", line 962, in create
    instance = ModelClass._default_manager.create(**validated_data)
               ^^^^^^^^^^^^^^^^^^^^^^^^^^^^^^^^^^^^^^^^^^^^^^^^^^^^
  File "C:\Users\kemosabe\Documents\traoning_management\backend\venv\Lib\site-packages\django\db\models\manager.py", line 87, in manager_method
    return getattr(self.get_queryset(), name)(*args, **kwargs)
           ^^^^^^^^^^^^^^^^^^^^^^^^^^^^^^^^^^^^^^^^^^^^^^^^^^^
  File "C:\Users\kemosabe\Documents\traoning_management\backend\venv\Lib\site-packages\django\db\models\query.py", line 658, in create
    obj.save(force_insert=True, using=self.db)
  File "C:\Users\kemosabe\Documents\traoning_management\backend\venv\Lib\site-packages\django\db\models\base.py", line 814, in save
    self.save_base(
  File "C:\Users\kemosabe\Documents\traoning_management\backend\venv\Lib\site-packages\django\db\models\base.py", line 877, in save_base
    updated = self._save_table(
              ^^^^^^^^^^^^^^^^^
  File "C:\Users\kemosabe\Documents\traoning_management\backend\venv\Lib\site-packages\django\db\models\base.py", line 1020, in _save_table
    results = self._do_insert(
              ^^^^^^^^^^^^^^^^
  File "C:\Users\kemosabe\Documents\traoning_management\backend\venv\Lib\site-packages\django\db\models\base.py", line 1061, in _do_insert
    return manager._insert(
           ^^^^^^^^^^^^^^^^
  File "C:\Users\kemosabe\Documents\traoning_management\backend\venv\Lib\site-packages\django\db\models\manager.py", line 87, in manager_method
    return getattr(self.get_queryset(), name)(*args, **kwargs)
           ^^^^^^^^^^^^^^^^^^^^^^^^^^^^^^^^^^^^^^^^^^^^^^^^^^^
  File "C:\Users\kemosabe\Documents\traoning_management\backend\venv\Lib\site-packages\django\db\models\query.py", line 1805, in _insert
    return query.get_compiler(using=using).execute_sql(returning_fields)
           ^^^^^^^^^^^^^^^^^^^^^^^^^^^^^^^^^^^^^^^^^^^^^^^^^^^^^^^^^^^^^
  File "C:\Users\kemosabe\Documents\traoning_management\backend\venv\Lib\site-packages\django\db\models\sql\compiler.py", line 1822, in execute_sql
    cursor.execute(sql, params)
  File "C:\Users\kemosabe\Documents\traoning_management\backend\venv\Lib\site-packages\django\db\backends\utils.py", line 67, in execute
    return self._execute_with_wrappers(
           ^^^^^^^^^^^^^^^^^^^^^^^^^^^^
  File "C:\Users\kemosabe\Documents\traoning_management\backend\venv\Lib\site-packages\django\db\backends\utils.py", line 80, in _execute_with_wrappers
    return executor(sql, params, many, context)
           ^^^^^^^^^^^^^^^^^^^^^^^^^^^^^^^^^^^^
  File "C:\Users\kemosabe\Documents\traoning_management\backend\venv\Lib\site-packages\django\db\backends\utils.py", line 84, in _execute
    with self.db.wrap_database_errors:
         ^^^^^^^^^^^^^^^^^^^^^^^^^^^^
  File "C:\Users\kemosabe\Documents\traoning_management\backend\venv\Lib\site-packages\django\db\utils.py", line 91, in __exit__
    raise dj_exc_value.with_traceback(traceback) from exc_value
  File "C:\Users\kemosabe\Documents\traoning_management\backend\venv\Lib\site-packages\django\db\backends\utils.py", line 89, in _execute
    return self.cursor.execute(sql, params)
           ^^^^^^^^^^^^^^^^^^^^^^^^^^^^^^^^
django.db.utils.IntegrityError: null value in column "user_profile_id" of relation "users_userskill" violates not-null constraint
DETAIL:  Failing row contains (1ba2cedd-2689-4a57-a4df-4c67d1fedc83, INTERMEDIATE, f, null, [], 33fac3e3-0195-476c-9b8e-fd79d79830e7, null, null).

ERROR 2024-10-30 18:36:20,850 log 19792 20008 Internal Server Error: /api/courses/courses/
Traceback (most recent call last):
  File "C:\Users\kemosabe\Documents\traoning_management\backend\venv\Lib\site-packages\django\db\backends\utils.py", line 89, in _execute
    return self.cursor.execute(sql, params)
           ^^^^^^^^^^^^^^^^^^^^^^^^^^^^^^^^
psycopg2.errors.UndefinedColumn: column courses_course.code does not exist
LINE 1: SELECT 1 AS "a" FROM "courses_course" WHERE "courses_course"...
                                                    ^


The above exception was the direct cause of the following exception:

Traceback (most recent call last):
  File "C:\Users\kemosabe\Documents\traoning_management\backend\venv\Lib\site-packages\django\core\handlers\exception.py", line 55, in inner
    response = get_response(request)
               ^^^^^^^^^^^^^^^^^^^^^
  File "C:\Users\kemosabe\Documents\traoning_management\backend\venv\Lib\site-packages\django\core\handlers\base.py", line 197, in _get_response
    response = wrapped_callback(request, *callback_args, **callback_kwargs)
               ^^^^^^^^^^^^^^^^^^^^^^^^^^^^^^^^^^^^^^^^^^^^^^^^^^^^^^^^^^^^
  File "C:\Program Files\WindowsApps\PythonSoftwareFoundation.Python.3.12_3.12.2032.0_x64__qbz5n2kfra8p0\Lib\contextlib.py", line 81, in inner
    return func(*args, **kwds)
           ^^^^^^^^^^^^^^^^^^^
  File "C:\Users\kemosabe\Documents\traoning_management\backend\venv\Lib\site-packages\django\views\decorators\csrf.py", line 56, in wrapper_view
    return view_func(*args, **kwargs)
           ^^^^^^^^^^^^^^^^^^^^^^^^^^
  File "C:\Users\kemosabe\Documents\traoning_management\backend\venv\Lib\site-packages\rest_framework\viewsets.py", line 125, in view
    return self.dispatch(request, *args, **kwargs)
           ^^^^^^^^^^^^^^^^^^^^^^^^^^^^^^^^^^^^^^^
  File "C:\Users\kemosabe\Documents\traoning_management\backend\venv\Lib\site-packages\rest_framework\views.py", line 509, in dispatch
    response = self.handle_exception(exc)
               ^^^^^^^^^^^^^^^^^^^^^^^^^^
  File "C:\Users\kemosabe\Documents\traoning_management\backend\venv\Lib\site-packages\rest_framework\views.py", line 469, in handle_exception
    self.raise_uncaught_exception(exc)
  File "C:\Users\kemosabe\Documents\traoning_management\backend\venv\Lib\site-packages\rest_framework\views.py", line 480, in raise_uncaught_exception
    raise exc
  File "C:\Users\kemosabe\Documents\traoning_management\backend\venv\Lib\site-packages\rest_framework\views.py", line 506, in dispatch
    response = handler(request, *args, **kwargs)
               ^^^^^^^^^^^^^^^^^^^^^^^^^^^^^^^^^
  File "C:\Users\kemosabe\Documents\traoning_management\backend\venv\Lib\site-packages\rest_framework\mixins.py", line 18, in create
    serializer.is_valid(raise_exception=True)
  File "C:\Users\kemosabe\Documents\traoning_management\backend\venv\Lib\site-packages\rest_framework\serializers.py", line 227, in is_valid
    self._validated_data = self.run_validation(self.initial_data)
                           ^^^^^^^^^^^^^^^^^^^^^^^^^^^^^^^^^^^^^^
  File "C:\Users\kemosabe\Documents\traoning_management\backend\venv\Lib\site-packages\rest_framework\serializers.py", line 426, in run_validation
    value = self.to_internal_value(data)
            ^^^^^^^^^^^^^^^^^^^^^^^^^^^^
  File "C:\Users\kemosabe\Documents\traoning_management\backend\venv\Lib\site-packages\rest_framework\serializers.py", line 483, in to_internal_value
    validated_value = field.run_validation(primitive_value)
                      ^^^^^^^^^^^^^^^^^^^^^^^^^^^^^^^^^^^^^
  File "C:\Users\kemosabe\Documents\traoning_management\backend\venv\Lib\site-packages\rest_framework\fields.py", line 751, in run_validation
    return super().run_validation(data)
           ^^^^^^^^^^^^^^^^^^^^^^^^^^^^
  File "C:\Users\kemosabe\Documents\traoning_management\backend\venv\Lib\site-packages\rest_framework\fields.py", line 548, in run_validation
    self.run_validators(value)
  File "C:\Users\kemosabe\Documents\traoning_management\backend\venv\Lib\site-packages\rest_framework\fields.py", line 560, in run_validators
    validator(value, self)
  File "C:\Users\kemosabe\Documents\traoning_management\backend\venv\Lib\site-packages\rest_framework\validators.py", line 73, in __call__
    if qs_exists(queryset):
       ^^^^^^^^^^^^^^^^^^^
  File "C:\Users\kemosabe\Documents\traoning_management\backend\venv\Lib\site-packages\rest_framework\validators.py", line 21, in qs_exists
    return queryset.exists()
           ^^^^^^^^^^^^^^^^^
  File "C:\Users\kemosabe\Documents\traoning_management\backend\venv\Lib\site-packages\django\db\models\query.py", line 1241, in exists
    return self.query.has_results(using=self.db)
           ^^^^^^^^^^^^^^^^^^^^^^^^^^^^^^^^^^^^^
  File "C:\Users\kemosabe\Documents\traoning_management\backend\venv\Lib\site-packages\django\db\models\sql\query.py", line 598, in has_results
    return compiler.has_results()
           ^^^^^^^^^^^^^^^^^^^^^^
  File "C:\Users\kemosabe\Documents\traoning_management\backend\venv\Lib\site-packages\django\db\models\sql\compiler.py", line 1530, in has_results
    return bool(self.execute_sql(SINGLE))
                ^^^^^^^^^^^^^^^^^^^^^^^^
  File "C:\Users\kemosabe\Documents\traoning_management\backend\venv\Lib\site-packages\django\db\models\sql\compiler.py", line 1562, in execute_sql
    cursor.execute(sql, params)
  File "C:\Users\kemosabe\Documents\traoning_management\backend\venv\Lib\site-packages\django\db\backends\utils.py", line 67, in execute
    return self._execute_with_wrappers(
           ^^^^^^^^^^^^^^^^^^^^^^^^^^^^
  File "C:\Users\kemosabe\Documents\traoning_management\backend\venv\Lib\site-packages\django\db\backends\utils.py", line 80, in _execute_with_wrappers
    return executor(sql, params, many, context)
           ^^^^^^^^^^^^^^^^^^^^^^^^^^^^^^^^^^^^
  File "C:\Users\kemosabe\Documents\traoning_management\backend\venv\Lib\site-packages\django\db\backends\utils.py", line 84, in _execute
    with self.db.wrap_database_errors:
         ^^^^^^^^^^^^^^^^^^^^^^^^^^^^
  File "C:\Users\kemosabe\Documents\traoning_management\backend\venv\Lib\site-packages\django\db\utils.py", line 91, in __exit__
    raise dj_exc_value.with_traceback(traceback) from exc_value
  File "C:\Users\kemosabe\Documents\traoning_management\backend\venv\Lib\site-packages\django\db\backends\utils.py", line 89, in _execute
    return self.cursor.execute(sql, params)
           ^^^^^^^^^^^^^^^^^^^^^^^^^^^^^^^^
django.db.utils.ProgrammingError: column courses_course.code does not exist
LINE 1: SELECT 1 AS "a" FROM "courses_course" WHERE "courses_course"...
                                                    ^

ERROR 2024-10-30 18:39:02,956 log 12128 17524 Internal Server Error: /api/courses/courses/
Traceback (most recent call last):
  File "C:\Users\kemosabe\Documents\traoning_management\backend\venv\Lib\site-packages\django\db\backends\utils.py", line 89, in _execute
    return self.cursor.execute(sql, params)
           ^^^^^^^^^^^^^^^^^^^^^^^^^^^^^^^^
psycopg2.errors.UndefinedColumn: column courses_course.code does not exist
LINE 1: SELECT 1 AS "a" FROM "courses_course" WHERE "courses_course"...
                                                    ^


The above exception was the direct cause of the following exception:

Traceback (most recent call last):
  File "C:\Users\kemosabe\Documents\traoning_management\backend\venv\Lib\site-packages\django\core\handlers\exception.py", line 55, in inner
    response = get_response(request)
               ^^^^^^^^^^^^^^^^^^^^^
  File "C:\Users\kemosabe\Documents\traoning_management\backend\venv\Lib\site-packages\django\core\handlers\base.py", line 197, in _get_response
    response = wrapped_callback(request, *callback_args, **callback_kwargs)
               ^^^^^^^^^^^^^^^^^^^^^^^^^^^^^^^^^^^^^^^^^^^^^^^^^^^^^^^^^^^^
  File "C:\Program Files\WindowsApps\PythonSoftwareFoundation.Python.3.12_3.12.2032.0_x64__qbz5n2kfra8p0\Lib\contextlib.py", line 81, in inner
    return func(*args, **kwds)
           ^^^^^^^^^^^^^^^^^^^
  File "C:\Users\kemosabe\Documents\traoning_management\backend\venv\Lib\site-packages\django\views\decorators\csrf.py", line 56, in wrapper_view
    return view_func(*args, **kwargs)
           ^^^^^^^^^^^^^^^^^^^^^^^^^^
  File "C:\Users\kemosabe\Documents\traoning_management\backend\venv\Lib\site-packages\rest_framework\viewsets.py", line 125, in view
    return self.dispatch(request, *args, **kwargs)
           ^^^^^^^^^^^^^^^^^^^^^^^^^^^^^^^^^^^^^^^
  File "C:\Users\kemosabe\Documents\traoning_management\backend\venv\Lib\site-packages\rest_framework\views.py", line 509, in dispatch
    response = self.handle_exception(exc)
               ^^^^^^^^^^^^^^^^^^^^^^^^^^
  File "C:\Users\kemosabe\Documents\traoning_management\backend\venv\Lib\site-packages\rest_framework\views.py", line 469, in handle_exception
    self.raise_uncaught_exception(exc)
  File "C:\Users\kemosabe\Documents\traoning_management\backend\venv\Lib\site-packages\rest_framework\views.py", line 480, in raise_uncaught_exception
    raise exc
  File "C:\Users\kemosabe\Documents\traoning_management\backend\venv\Lib\site-packages\rest_framework\views.py", line 506, in dispatch
    response = handler(request, *args, **kwargs)
               ^^^^^^^^^^^^^^^^^^^^^^^^^^^^^^^^^
  File "C:\Users\kemosabe\Documents\traoning_management\backend\venv\Lib\site-packages\rest_framework\mixins.py", line 18, in create
    serializer.is_valid(raise_exception=True)
  File "C:\Users\kemosabe\Documents\traoning_management\backend\venv\Lib\site-packages\rest_framework\serializers.py", line 227, in is_valid
    self._validated_data = self.run_validation(self.initial_data)
                           ^^^^^^^^^^^^^^^^^^^^^^^^^^^^^^^^^^^^^^
  File "C:\Users\kemosabe\Documents\traoning_management\backend\venv\Lib\site-packages\rest_framework\serializers.py", line 426, in run_validation
    value = self.to_internal_value(data)
            ^^^^^^^^^^^^^^^^^^^^^^^^^^^^
  File "C:\Users\kemosabe\Documents\traoning_management\backend\venv\Lib\site-packages\rest_framework\serializers.py", line 483, in to_internal_value
    validated_value = field.run_validation(primitive_value)
                      ^^^^^^^^^^^^^^^^^^^^^^^^^^^^^^^^^^^^^
  File "C:\Users\kemosabe\Documents\traoning_management\backend\venv\Lib\site-packages\rest_framework\fields.py", line 751, in run_validation
    return super().run_validation(data)
           ^^^^^^^^^^^^^^^^^^^^^^^^^^^^
  File "C:\Users\kemosabe\Documents\traoning_management\backend\venv\Lib\site-packages\rest_framework\fields.py", line 548, in run_validation
    self.run_validators(value)
  File "C:\Users\kemosabe\Documents\traoning_management\backend\venv\Lib\site-packages\rest_framework\fields.py", line 560, in run_validators
    validator(value, self)
  File "C:\Users\kemosabe\Documents\traoning_management\backend\venv\Lib\site-packages\rest_framework\validators.py", line 73, in __call__
    if qs_exists(queryset):
       ^^^^^^^^^^^^^^^^^^^
  File "C:\Users\kemosabe\Documents\traoning_management\backend\venv\Lib\site-packages\rest_framework\validators.py", line 21, in qs_exists
    return queryset.exists()
           ^^^^^^^^^^^^^^^^^
  File "C:\Users\kemosabe\Documents\traoning_management\backend\venv\Lib\site-packages\django\db\models\query.py", line 1241, in exists
    return self.query.has_results(using=self.db)
           ^^^^^^^^^^^^^^^^^^^^^^^^^^^^^^^^^^^^^
  File "C:\Users\kemosabe\Documents\traoning_management\backend\venv\Lib\site-packages\django\db\models\sql\query.py", line 598, in has_results
    return compiler.has_results()
           ^^^^^^^^^^^^^^^^^^^^^^
  File "C:\Users\kemosabe\Documents\traoning_management\backend\venv\Lib\site-packages\django\db\models\sql\compiler.py", line 1530, in has_results
    return bool(self.execute_sql(SINGLE))
                ^^^^^^^^^^^^^^^^^^^^^^^^
  File "C:\Users\kemosabe\Documents\traoning_management\backend\venv\Lib\site-packages\django\db\models\sql\compiler.py", line 1562, in execute_sql
    cursor.execute(sql, params)
  File "C:\Users\kemosabe\Documents\traoning_management\backend\venv\Lib\site-packages\django\db\backends\utils.py", line 67, in execute
    return self._execute_with_wrappers(
           ^^^^^^^^^^^^^^^^^^^^^^^^^^^^
  File "C:\Users\kemosabe\Documents\traoning_management\backend\venv\Lib\site-packages\django\db\backends\utils.py", line 80, in _execute_with_wrappers
    return executor(sql, params, many, context)
           ^^^^^^^^^^^^^^^^^^^^^^^^^^^^^^^^^^^^
  File "C:\Users\kemosabe\Documents\traoning_management\backend\venv\Lib\site-packages\django\db\backends\utils.py", line 84, in _execute
    with self.db.wrap_database_errors:
         ^^^^^^^^^^^^^^^^^^^^^^^^^^^^
  File "C:\Users\kemosabe\Documents\traoning_management\backend\venv\Lib\site-packages\django\db\utils.py", line 91, in __exit__
    raise dj_exc_value.with_traceback(traceback) from exc_value
  File "C:\Users\kemosabe\Documents\traoning_management\backend\venv\Lib\site-packages\django\db\backends\utils.py", line 89, in _execute
    return self.cursor.execute(sql, params)
           ^^^^^^^^^^^^^^^^^^^^^^^^^^^^^^^^
django.db.utils.ProgrammingError: column courses_course.code does not exist
LINE 1: SELECT 1 AS "a" FROM "courses_course" WHERE "courses_course"...
                                                    ^

ERROR 2024-10-30 18:46:47,366 log 14340 2196 Internal Server Error: /api/courses/courses/
Traceback (most recent call last):
  File "C:\Users\kemosabe\Documents\traoning_management\backend\venv\Lib\site-packages\django\db\backends\utils.py", line 89, in _execute
    return self.cursor.execute(sql, params)
           ^^^^^^^^^^^^^^^^^^^^^^^^^^^^^^^^
psycopg2.errors.UndefinedTable: relation "courses_course" does not exist
LINE 1: SELECT 1 AS "a" FROM "courses_course" WHERE "courses_course"...
                             ^


The above exception was the direct cause of the following exception:

Traceback (most recent call last):
  File "C:\Users\kemosabe\Documents\traoning_management\backend\venv\Lib\site-packages\django\core\handlers\exception.py", line 55, in inner
    response = get_response(request)
               ^^^^^^^^^^^^^^^^^^^^^
  File "C:\Users\kemosabe\Documents\traoning_management\backend\venv\Lib\site-packages\django\core\handlers\base.py", line 197, in _get_response
    response = wrapped_callback(request, *callback_args, **callback_kwargs)
               ^^^^^^^^^^^^^^^^^^^^^^^^^^^^^^^^^^^^^^^^^^^^^^^^^^^^^^^^^^^^
  File "C:\Program Files\WindowsApps\PythonSoftwareFoundation.Python.3.12_3.12.2032.0_x64__qbz5n2kfra8p0\Lib\contextlib.py", line 81, in inner
    return func(*args, **kwds)
           ^^^^^^^^^^^^^^^^^^^
  File "C:\Users\kemosabe\Documents\traoning_management\backend\venv\Lib\site-packages\django\views\decorators\csrf.py", line 56, in wrapper_view
    return view_func(*args, **kwargs)
           ^^^^^^^^^^^^^^^^^^^^^^^^^^
  File "C:\Users\kemosabe\Documents\traoning_management\backend\venv\Lib\site-packages\rest_framework\viewsets.py", line 125, in view
    return self.dispatch(request, *args, **kwargs)
           ^^^^^^^^^^^^^^^^^^^^^^^^^^^^^^^^^^^^^^^
  File "C:\Users\kemosabe\Documents\traoning_management\backend\venv\Lib\site-packages\rest_framework\views.py", line 509, in dispatch
    response = self.handle_exception(exc)
               ^^^^^^^^^^^^^^^^^^^^^^^^^^
  File "C:\Users\kemosabe\Documents\traoning_management\backend\venv\Lib\site-packages\rest_framework\views.py", line 469, in handle_exception
    self.raise_uncaught_exception(exc)
  File "C:\Users\kemosabe\Documents\traoning_management\backend\venv\Lib\site-packages\rest_framework\views.py", line 480, in raise_uncaught_exception
    raise exc
  File "C:\Users\kemosabe\Documents\traoning_management\backend\venv\Lib\site-packages\rest_framework\views.py", line 506, in dispatch
    response = handler(request, *args, **kwargs)
               ^^^^^^^^^^^^^^^^^^^^^^^^^^^^^^^^^
  File "C:\Users\kemosabe\Documents\traoning_management\backend\venv\Lib\site-packages\rest_framework\mixins.py", line 18, in create
    serializer.is_valid(raise_exception=True)
  File "C:\Users\kemosabe\Documents\traoning_management\backend\venv\Lib\site-packages\rest_framework\serializers.py", line 227, in is_valid
    self._validated_data = self.run_validation(self.initial_data)
                           ^^^^^^^^^^^^^^^^^^^^^^^^^^^^^^^^^^^^^^
  File "C:\Users\kemosabe\Documents\traoning_management\backend\venv\Lib\site-packages\rest_framework\serializers.py", line 426, in run_validation
    value = self.to_internal_value(data)
            ^^^^^^^^^^^^^^^^^^^^^^^^^^^^
  File "C:\Users\kemosabe\Documents\traoning_management\backend\venv\Lib\site-packages\rest_framework\serializers.py", line 483, in to_internal_value
    validated_value = field.run_validation(primitive_value)
                      ^^^^^^^^^^^^^^^^^^^^^^^^^^^^^^^^^^^^^
  File "C:\Users\kemosabe\Documents\traoning_management\backend\venv\Lib\site-packages\rest_framework\fields.py", line 751, in run_validation
    return super().run_validation(data)
           ^^^^^^^^^^^^^^^^^^^^^^^^^^^^
  File "C:\Users\kemosabe\Documents\traoning_management\backend\venv\Lib\site-packages\rest_framework\fields.py", line 548, in run_validation
    self.run_validators(value)
  File "C:\Users\kemosabe\Documents\traoning_management\backend\venv\Lib\site-packages\rest_framework\fields.py", line 560, in run_validators
    validator(value, self)
  File "C:\Users\kemosabe\Documents\traoning_management\backend\venv\Lib\site-packages\rest_framework\validators.py", line 73, in __call__
    if qs_exists(queryset):
       ^^^^^^^^^^^^^^^^^^^
  File "C:\Users\kemosabe\Documents\traoning_management\backend\venv\Lib\site-packages\rest_framework\validators.py", line 21, in qs_exists
    return queryset.exists()
           ^^^^^^^^^^^^^^^^^
  File "C:\Users\kemosabe\Documents\traoning_management\backend\venv\Lib\site-packages\django\db\models\query.py", line 1241, in exists
    return self.query.has_results(using=self.db)
           ^^^^^^^^^^^^^^^^^^^^^^^^^^^^^^^^^^^^^
  File "C:\Users\kemosabe\Documents\traoning_management\backend\venv\Lib\site-packages\django\db\models\sql\query.py", line 598, in has_results
    return compiler.has_results()
           ^^^^^^^^^^^^^^^^^^^^^^
  File "C:\Users\kemosabe\Documents\traoning_management\backend\venv\Lib\site-packages\django\db\models\sql\compiler.py", line 1530, in has_results
    return bool(self.execute_sql(SINGLE))
                ^^^^^^^^^^^^^^^^^^^^^^^^
  File "C:\Users\kemosabe\Documents\traoning_management\backend\venv\Lib\site-packages\django\db\models\sql\compiler.py", line 1562, in execute_sql
    cursor.execute(sql, params)
  File "C:\Users\kemosabe\Documents\traoning_management\backend\venv\Lib\site-packages\django\db\backends\utils.py", line 67, in execute
    return self._execute_with_wrappers(
           ^^^^^^^^^^^^^^^^^^^^^^^^^^^^
  File "C:\Users\kemosabe\Documents\traoning_management\backend\venv\Lib\site-packages\django\db\backends\utils.py", line 80, in _execute_with_wrappers
    return executor(sql, params, many, context)
           ^^^^^^^^^^^^^^^^^^^^^^^^^^^^^^^^^^^^
  File "C:\Users\kemosabe\Documents\traoning_management\backend\venv\Lib\site-packages\django\db\backends\utils.py", line 84, in _execute
    with self.db.wrap_database_errors:
         ^^^^^^^^^^^^^^^^^^^^^^^^^^^^
  File "C:\Users\kemosabe\Documents\traoning_management\backend\venv\Lib\site-packages\django\db\utils.py", line 91, in __exit__
    raise dj_exc_value.with_traceback(traceback) from exc_value
  File "C:\Users\kemosabe\Documents\traoning_management\backend\venv\Lib\site-packages\django\db\backends\utils.py", line 89, in _execute
    return self.cursor.execute(sql, params)
           ^^^^^^^^^^^^^^^^^^^^^^^^^^^^^^^^
django.db.utils.ProgrammingError: relation "courses_course" does not exist
LINE 1: SELECT 1 AS "a" FROM "courses_course" WHERE "courses_course"...
                             ^

ERROR 2024-10-30 18:48:34,023 log 12548 20172 Internal Server Error: /api/courses/courses/56da4fe0-2b0d-47ff-a459-f6de90292335/enroll/
Traceback (most recent call last):
  File "C:\Users\kemosabe\Documents\traoning_management\backend\venv\Lib\site-packages\django\core\handlers\exception.py", line 55, in inner
    response = get_response(request)
               ^^^^^^^^^^^^^^^^^^^^^
  File "C:\Users\kemosabe\Documents\traoning_management\backend\venv\Lib\site-packages\django\core\handlers\base.py", line 197, in _get_response
    response = wrapped_callback(request, *callback_args, **callback_kwargs)
               ^^^^^^^^^^^^^^^^^^^^^^^^^^^^^^^^^^^^^^^^^^^^^^^^^^^^^^^^^^^^
  File "C:\Program Files\WindowsApps\PythonSoftwareFoundation.Python.3.12_3.12.2032.0_x64__qbz5n2kfra8p0\Lib\contextlib.py", line 81, in inner
    return func(*args, **kwds)
           ^^^^^^^^^^^^^^^^^^^
  File "C:\Users\kemosabe\Documents\traoning_management\backend\venv\Lib\site-packages\django\views\decorators\csrf.py", line 56, in wrapper_view
    return view_func(*args, **kwargs)
           ^^^^^^^^^^^^^^^^^^^^^^^^^^
  File "C:\Users\kemosabe\Documents\traoning_management\backend\venv\Lib\site-packages\rest_framework\viewsets.py", line 125, in view
    return self.dispatch(request, *args, **kwargs)
           ^^^^^^^^^^^^^^^^^^^^^^^^^^^^^^^^^^^^^^^
  File "C:\Users\kemosabe\Documents\traoning_management\backend\venv\Lib\site-packages\rest_framework\views.py", line 509, in dispatch
    response = self.handle_exception(exc)
               ^^^^^^^^^^^^^^^^^^^^^^^^^^
  File "C:\Users\kemosabe\Documents\traoning_management\backend\venv\Lib\site-packages\rest_framework\views.py", line 469, in handle_exception
    self.raise_uncaught_exception(exc)
  File "C:\Users\kemosabe\Documents\traoning_management\backend\venv\Lib\site-packages\rest_framework\views.py", line 480, in raise_uncaught_exception
    raise exc
  File "C:\Users\kemosabe\Documents\traoning_management\backend\venv\Lib\site-packages\rest_framework\views.py", line 506, in dispatch
    response = handler(request, *args, **kwargs)
               ^^^^^^^^^^^^^^^^^^^^^^^^^^^^^^^^^
  File "C:\Users\kemosabe\Documents\traoning_management\backend\apps\courses\views.py", line 70, in enroll
    enrollment = Enrollment.objects.create(
                 ^^^^^^^^^^^^^^^^^^^^^^^^^^
  File "C:\Users\kemosabe\Documents\traoning_management\backend\venv\Lib\site-packages\django\db\models\manager.py", line 87, in manager_method
    return getattr(self.get_queryset(), name)(*args, **kwargs)
           ^^^^^^^^^^^^^^^^^^^^^^^^^^^^^^^^^^^^^^^^^^^^^^^^^^^
  File "C:\Users\kemosabe\Documents\traoning_management\backend\venv\Lib\site-packages\django\db\models\query.py", line 658, in create
    obj.save(force_insert=True, using=self.db)
  File "C:\Users\kemosabe\Documents\traoning_management\backend\apps\courses\models.py", line 448, in save
    old_status = Enrollment.objects.get(pk=self.pk).status
                 ^^^^^^^^^^^^^^^^^^^^^^^^^^^^^^^^^^
  File "C:\Users\kemosabe\Documents\traoning_management\backend\venv\Lib\site-packages\django\db\models\manager.py", line 87, in manager_method
    return getattr(self.get_queryset(), name)(*args, **kwargs)
           ^^^^^^^^^^^^^^^^^^^^^^^^^^^^^^^^^^^^^^^^^^^^^^^^^^^
  File "C:\Users\kemosabe\Documents\traoning_management\backend\venv\Lib\site-packages\django\db\models\query.py", line 637, in get
    raise self.model.DoesNotExist(
apps.courses.models.Enrollment.DoesNotExist: Enrollment matching query does not exist.
ERROR 2024-10-30 23:38:22,382 log 14576 18944 Internal Server Error: /api/courses/courses/0549dfab-c65f-4a81-8ba5-9df0e0ad320d/enroll/
Traceback (most recent call last):
  File "C:\Users\kemosabe\Documents\traoning_management\backend\venv\Lib\site-packages\django\core\handlers\exception.py", line 55, in inner
    response = get_response(request)
               ^^^^^^^^^^^^^^^^^^^^^
  File "C:\Users\kemosabe\Documents\traoning_management\backend\venv\Lib\site-packages\django\core\handlers\base.py", line 197, in _get_response
    response = wrapped_callback(request, *callback_args, **callback_kwargs)
               ^^^^^^^^^^^^^^^^^^^^^^^^^^^^^^^^^^^^^^^^^^^^^^^^^^^^^^^^^^^^
  File "C:\Program Files\WindowsApps\PythonSoftwareFoundation.Python.3.12_3.12.2032.0_x64__qbz5n2kfra8p0\Lib\contextlib.py", line 81, in inner
    return func(*args, **kwds)
           ^^^^^^^^^^^^^^^^^^^
  File "C:\Users\kemosabe\Documents\traoning_management\backend\venv\Lib\site-packages\django\views\decorators\csrf.py", line 56, in wrapper_view
    return view_func(*args, **kwargs)
           ^^^^^^^^^^^^^^^^^^^^^^^^^^
  File "C:\Users\kemosabe\Documents\traoning_management\backend\venv\Lib\site-packages\rest_framework\viewsets.py", line 125, in view
    return self.dispatch(request, *args, **kwargs)
           ^^^^^^^^^^^^^^^^^^^^^^^^^^^^^^^^^^^^^^^
  File "C:\Users\kemosabe\Documents\traoning_management\backend\venv\Lib\site-packages\rest_framework\views.py", line 509, in dispatch
    response = self.handle_exception(exc)
               ^^^^^^^^^^^^^^^^^^^^^^^^^^
  File "C:\Users\kemosabe\Documents\traoning_management\backend\venv\Lib\site-packages\rest_framework\views.py", line 469, in handle_exception
    self.raise_uncaught_exception(exc)
  File "C:\Users\kemosabe\Documents\traoning_management\backend\venv\Lib\site-packages\rest_framework\views.py", line 480, in raise_uncaught_exception
    raise exc
  File "C:\Users\kemosabe\Documents\traoning_management\backend\venv\Lib\site-packages\rest_framework\views.py", line 506, in dispatch
    response = handler(request, *args, **kwargs)
               ^^^^^^^^^^^^^^^^^^^^^^^^^^^^^^^^^
  File "C:\Users\kemosabe\Documents\traoning_management\backend\apps\courses\views.py", line 70, in enroll
    enrollment = Enrollment.objects.create(
                 ^^^^^^^^^^^^^^^^^^^^^^^^^^
  File "C:\Users\kemosabe\Documents\traoning_management\backend\venv\Lib\site-packages\django\db\models\manager.py", line 87, in manager_method
    return getattr(self.get_queryset(), name)(*args, **kwargs)
           ^^^^^^^^^^^^^^^^^^^^^^^^^^^^^^^^^^^^^^^^^^^^^^^^^^^
  File "C:\Users\kemosabe\Documents\traoning_management\backend\venv\Lib\site-packages\django\db\models\query.py", line 658, in create
    obj.save(force_insert=True, using=self.db)
  File "C:\Users\kemosabe\Documents\traoning_management\backend\apps\courses\models.py", line 448, in save
    old_status = Enrollment.objects.get(pk=self.pk).status
                 ^^^^^^^^^^^^^^^^^^^^^^^^^^^^^^^^^^
  File "C:\Users\kemosabe\Documents\traoning_management\backend\venv\Lib\site-packages\django\db\models\manager.py", line 87, in manager_method
    return getattr(self.get_queryset(), name)(*args, **kwargs)
           ^^^^^^^^^^^^^^^^^^^^^^^^^^^^^^^^^^^^^^^^^^^^^^^^^^^
  File "C:\Users\kemosabe\Documents\traoning_management\backend\venv\Lib\site-packages\django\db\models\query.py", line 637, in get
    raise self.model.DoesNotExist(
apps.courses.models.Enrollment.DoesNotExist: Enrollment matching query does not exist.
ERROR 2024-10-31 12:22:52,576 log 6432 12452 Internal Server Error: /api/courses/courses/e14ca8d7-b2d0-4d92-9306-bbe14822bcca/enroll/
Traceback (most recent call last):
  File "C:\Users\kemosabe\Documents\traoning_management\backend\venv\Lib\site-packages\django\core\handlers\exception.py", line 55, in inner
    response = get_response(request)
               ^^^^^^^^^^^^^^^^^^^^^
  File "C:\Users\kemosabe\Documents\traoning_management\backend\venv\Lib\site-packages\django\core\handlers\base.py", line 197, in _get_response
    response = wrapped_callback(request, *callback_args, **callback_kwargs)
               ^^^^^^^^^^^^^^^^^^^^^^^^^^^^^^^^^^^^^^^^^^^^^^^^^^^^^^^^^^^^
  File "C:\Program Files\WindowsApps\PythonSoftwareFoundation.Python.3.12_3.12.2032.0_x64__qbz5n2kfra8p0\Lib\contextlib.py", line 81, in inner
    return func(*args, **kwds)
           ^^^^^^^^^^^^^^^^^^^
  File "C:\Users\kemosabe\Documents\traoning_management\backend\venv\Lib\site-packages\django\views\decorators\csrf.py", line 56, in wrapper_view
    return view_func(*args, **kwargs)
           ^^^^^^^^^^^^^^^^^^^^^^^^^^
  File "C:\Users\kemosabe\Documents\traoning_management\backend\venv\Lib\site-packages\rest_framework\viewsets.py", line 125, in view
    return self.dispatch(request, *args, **kwargs)
           ^^^^^^^^^^^^^^^^^^^^^^^^^^^^^^^^^^^^^^^
  File "C:\Users\kemosabe\Documents\traoning_management\backend\venv\Lib\site-packages\rest_framework\views.py", line 509, in dispatch
    response = self.handle_exception(exc)
               ^^^^^^^^^^^^^^^^^^^^^^^^^^
  File "C:\Users\kemosabe\Documents\traoning_management\backend\venv\Lib\site-packages\rest_framework\views.py", line 469, in handle_exception
    self.raise_uncaught_exception(exc)
  File "C:\Users\kemosabe\Documents\traoning_management\backend\venv\Lib\site-packages\rest_framework\views.py", line 480, in raise_uncaught_exception
    raise exc
  File "C:\Users\kemosabe\Documents\traoning_management\backend\venv\Lib\site-packages\rest_framework\views.py", line 506, in dispatch
    response = handler(request, *args, **kwargs)
               ^^^^^^^^^^^^^^^^^^^^^^^^^^^^^^^^^
  File "C:\Users\kemosabe\Documents\traoning_management\backend\apps\courses\views.py", line 70, in enroll
    enrollment = Enrollment.objects.create(
                 ^^^^^^^^^^^^^^^^^^^^^^^^^^
  File "C:\Users\kemosabe\Documents\traoning_management\backend\venv\Lib\site-packages\django\db\models\manager.py", line 87, in manager_method
    return getattr(self.get_queryset(), name)(*args, **kwargs)
           ^^^^^^^^^^^^^^^^^^^^^^^^^^^^^^^^^^^^^^^^^^^^^^^^^^^
  File "C:\Users\kemosabe\Documents\traoning_management\backend\venv\Lib\site-packages\django\db\models\query.py", line 658, in create
    obj.save(force_insert=True, using=self.db)
  File "C:\Users\kemosabe\Documents\traoning_management\backend\apps\courses\models.py", line 448, in save
    old_status = Enrollment.objects.get(pk=self.pk).status
                 ^^^^^^^^^^^^^^^^^^^^^^^^^^^^^^^^^^
  File "C:\Users\kemosabe\Documents\traoning_management\backend\venv\Lib\site-packages\django\db\models\manager.py", line 87, in manager_method
    return getattr(self.get_queryset(), name)(*args, **kwargs)
           ^^^^^^^^^^^^^^^^^^^^^^^^^^^^^^^^^^^^^^^^^^^^^^^^^^^
  File "C:\Users\kemosabe\Documents\traoning_management\backend\venv\Lib\site-packages\django\db\models\query.py", line 637, in get
    raise self.model.DoesNotExist(
apps.courses.models.Enrollment.DoesNotExist: Enrollment matching query does not exist.
